2019-03-15 11:45:07,070 ERROR: Exception on /reset_password_request [POST] [in c:\dudin\microblog\venv\lib\site-packages\flask\app.py:1761]
Traceback (most recent call last):
  File "c:\dudin\microblog\venv\lib\site-packages\flask\app.py", line 2292, in wsgi_app
    response = self.full_dispatch_request()
  File "c:\dudin\microblog\venv\lib\site-packages\flask\app.py", line 1815, in full_dispatch_request
    rv = self.handle_user_exception(e)
  File "c:\dudin\microblog\venv\lib\site-packages\flask\app.py", line 1718, in handle_user_exception
    reraise(exc_type, exc_value, tb)
  File "c:\dudin\microblog\venv\lib\site-packages\flask\_compat.py", line 35, in reraise
    raise value
  File "c:\dudin\microblog\venv\lib\site-packages\flask\app.py", line 1813, in full_dispatch_request
    rv = self.dispatch_request()
  File "c:\dudin\microblog\venv\lib\site-packages\flask\app.py", line 1799, in dispatch_request
    return self.view_functions[rule.endpoint](**req.view_args)
  File "C:\Dudin\microblog\app\routes.py", line 154, in reset_password_request
    send_password_reset_email(user)
  File "C:\Dudin\microblog\app\email.py", line 20, in send_password_reset_email
    user = user, token=token))
  File "C:\Dudin\microblog\app\email.py", line 10, in send_mail
    mail.send(msg)
  File "c:\dudin\microblog\venv\lib\site-packages\flask_mail.py", line 491, in send
    with self.connect() as connection:
  File "c:\dudin\microblog\venv\lib\site-packages\flask_mail.py", line 144, in __enter__
    self.host = self.configure_host()
  File "c:\dudin\microblog\venv\lib\site-packages\flask_mail.py", line 158, in configure_host
    host = smtplib.SMTP(self.mail.server, self.mail.port)
  File "C:\Users\student.dit\AppData\Local\Programs\Python\Python37-32\lib\smtplib.py", line 251, in __init__
    (code, msg) = self.connect(host, port)
  File "C:\Users\student.dit\AppData\Local\Programs\Python\Python37-32\lib\smtplib.py", line 336, in connect
    self.sock = self._get_socket(host, port, self.timeout)
  File "C:\Users\student.dit\AppData\Local\Programs\Python\Python37-32\lib\smtplib.py", line 307, in _get_socket
    self.source_address)
  File "C:\Users\student.dit\AppData\Local\Programs\Python\Python37-32\lib\socket.py", line 727, in create_connection
    raise err
  File "C:\Users\student.dit\AppData\Local\Programs\Python\Python37-32\lib\socket.py", line 716, in create_connection
    sock.connect(sa)
TimeoutError: [WinError 10060] Попытка установить соединение была безуспешной, т.к. от другого компьютера за требуемое время не получен нужный отклик, или было разорвано уже установленное соединение из-за неверного отклика уже подключенного компьютера
2019-03-15 15:01:52,450 ERROR: Exception on /reset_password_request [POST] [in c:\dudin\microblog\venv\lib\site-packages\flask\app.py:1761]
Traceback (most recent call last):
  File "c:\dudin\microblog\venv\lib\site-packages\flask\app.py", line 2292, in wsgi_app
    response = self.full_dispatch_request()
  File "c:\dudin\microblog\venv\lib\site-packages\flask\app.py", line 1815, in full_dispatch_request
    rv = self.handle_user_exception(e)
  File "c:\dudin\microblog\venv\lib\site-packages\flask\app.py", line 1718, in handle_user_exception
    reraise(exc_type, exc_value, tb)
  File "c:\dudin\microblog\venv\lib\site-packages\flask\_compat.py", line 35, in reraise
    raise value
  File "c:\dudin\microblog\venv\lib\site-packages\flask\app.py", line 1813, in full_dispatch_request
    rv = self.dispatch_request()
  File "c:\dudin\microblog\venv\lib\site-packages\flask\app.py", line 1799, in dispatch_request
    return self.view_functions[rule.endpoint](**req.view_args)
  File "C:\Dudin\microblog\app\routes.py", line 154, in reset_password_request
    send_password_reset_email(user)
  File "C:\Dudin\microblog\app\email.py", line 20, in send_password_reset_email
    user = user, token=token))
  File "C:\Dudin\microblog\app\email.py", line 10, in send_mail
    mail.send(msg)
  File "c:\dudin\microblog\venv\lib\site-packages\flask_mail.py", line 491, in send
    with self.connect() as connection:
  File "c:\dudin\microblog\venv\lib\site-packages\flask_mail.py", line 144, in __enter__
    self.host = self.configure_host()
  File "c:\dudin\microblog\venv\lib\site-packages\flask_mail.py", line 158, in configure_host
    host = smtplib.SMTP(self.mail.server, self.mail.port)
  File "C:\Users\student.dit\AppData\Local\Programs\Python\Python37-32\lib\smtplib.py", line 251, in __init__
    (code, msg) = self.connect(host, port)
  File "C:\Users\student.dit\AppData\Local\Programs\Python\Python37-32\lib\smtplib.py", line 336, in connect
    self.sock = self._get_socket(host, port, self.timeout)
  File "C:\Users\student.dit\AppData\Local\Programs\Python\Python37-32\lib\smtplib.py", line 307, in _get_socket
    self.source_address)
  File "C:\Users\student.dit\AppData\Local\Programs\Python\Python37-32\lib\socket.py", line 727, in create_connection
    raise err
  File "C:\Users\student.dit\AppData\Local\Programs\Python\Python37-32\lib\socket.py", line 716, in create_connection
    sock.connect(sa)
TimeoutError: [WinError 10060] Попытка установить соединение была безуспешной, т.к. от другого компьютера за требуемое время не получен нужный отклик, или было разорвано уже установленное соединение из-за неверного отклика уже подключенного компьютера
2019-03-15 15:02:37,843 INFO: Microblog startup [in C:\Dudin\microblog\microblog.py:36]
2019-03-15 15:02:54,948 ERROR: Exception on /reset_password_request [POST] [in c:\dudin\microblog\venv\lib\site-packages\flask\app.py:1761]
Traceback (most recent call last):
  File "c:\dudin\microblog\venv\lib\site-packages\flask\app.py", line 2292, in wsgi_app
    response = self.full_dispatch_request()
  File "c:\dudin\microblog\venv\lib\site-packages\flask\app.py", line 1815, in full_dispatch_request
    rv = self.handle_user_exception(e)
  File "c:\dudin\microblog\venv\lib\site-packages\flask\app.py", line 1718, in handle_user_exception
    reraise(exc_type, exc_value, tb)
  File "c:\dudin\microblog\venv\lib\site-packages\flask\_compat.py", line 35, in reraise
    raise value
  File "c:\dudin\microblog\venv\lib\site-packages\flask\app.py", line 1813, in full_dispatch_request
    rv = self.dispatch_request()
  File "c:\dudin\microblog\venv\lib\site-packages\flask\app.py", line 1799, in dispatch_request
    return self.view_functions[rule.endpoint](**req.view_args)
  File "C:\Dudin\microblog\app\routes.py", line 154, in reset_password_request
    send_password_reset_email(user)
  File "C:\Dudin\microblog\app\email.py", line 20, in send_password_reset_email
    user = user, token=token))
  File "C:\Dudin\microblog\app\email.py", line 10, in send_email
    mail.send(msg)
  File "c:\dudin\microblog\venv\lib\site-packages\flask_mail.py", line 491, in send
    with self.connect() as connection:
  File "c:\dudin\microblog\venv\lib\site-packages\flask_mail.py", line 144, in __enter__
    self.host = self.configure_host()
  File "c:\dudin\microblog\venv\lib\site-packages\flask_mail.py", line 163, in configure_host
    host.starttls()
  File "C:\Users\student.dit\AppData\Local\Programs\Python\Python37-32\lib\smtplib.py", line 752, in starttls
    "STARTTLS extension not supported by server.")
smtplib.SMTPNotSupportedError: STARTTLS extension not supported by server.
2019-03-15 15:03:14,945 ERROR: Exception on /reset_password_request [POST] [in c:\dudin\microblog\venv\lib\site-packages\flask\app.py:1761]
Traceback (most recent call last):
  File "c:\dudin\microblog\venv\lib\site-packages\flask\app.py", line 2292, in wsgi_app
    response = self.full_dispatch_request()
  File "c:\dudin\microblog\venv\lib\site-packages\flask\app.py", line 1815, in full_dispatch_request
    rv = self.handle_user_exception(e)
  File "c:\dudin\microblog\venv\lib\site-packages\flask\app.py", line 1718, in handle_user_exception
    reraise(exc_type, exc_value, tb)
  File "c:\dudin\microblog\venv\lib\site-packages\flask\_compat.py", line 35, in reraise
    raise value
  File "c:\dudin\microblog\venv\lib\site-packages\flask\app.py", line 1813, in full_dispatch_request
    rv = self.dispatch_request()
  File "c:\dudin\microblog\venv\lib\site-packages\flask\app.py", line 1799, in dispatch_request
    return self.view_functions[rule.endpoint](**req.view_args)
  File "C:\Dudin\microblog\app\routes.py", line 154, in reset_password_request
    send_password_reset_email(user)
  File "C:\Dudin\microblog\app\email.py", line 20, in send_password_reset_email
    user = user, token=token))
  File "C:\Dudin\microblog\app\email.py", line 10, in send_email
    mail.send(msg)
  File "c:\dudin\microblog\venv\lib\site-packages\flask_mail.py", line 491, in send
    with self.connect() as connection:
  File "c:\dudin\microblog\venv\lib\site-packages\flask_mail.py", line 144, in __enter__
    self.host = self.configure_host()
  File "c:\dudin\microblog\venv\lib\site-packages\flask_mail.py", line 163, in configure_host
    host.starttls()
  File "C:\Users\student.dit\AppData\Local\Programs\Python\Python37-32\lib\smtplib.py", line 752, in starttls
    "STARTTLS extension not supported by server.")
smtplib.SMTPNotSupportedError: STARTTLS extension not supported by server.
